[2023-06-11 04:40:09,164] {taskinstance.py:1179} INFO - Dependencies all met for <TaskInstance: 01_unscheduled.calculate_stats manual__2023-06-11T03:54:24.205713+00:00 [queued]>
[2023-06-11 04:40:09,171] {taskinstance.py:1179} INFO - Dependencies all met for <TaskInstance: 01_unscheduled.calculate_stats manual__2023-06-11T03:54:24.205713+00:00 [queued]>
[2023-06-11 04:40:09,172] {taskinstance.py:1376} INFO - 
--------------------------------------------------------------------------------
[2023-06-11 04:40:09,174] {taskinstance.py:1377} INFO - Starting attempt 1 of 1
[2023-06-11 04:40:09,174] {taskinstance.py:1378} INFO - 
--------------------------------------------------------------------------------
[2023-06-11 04:40:09,182] {taskinstance.py:1397} INFO - Executing <Task(PythonOperator): calculate_stats> on 2023-06-11 03:54:24.205713+00:00
[2023-06-11 04:40:09,186] {standard_task_runner.py:52} INFO - Started process 28878 to run task
[2023-06-11 04:40:09,189] {standard_task_runner.py:79} INFO - Running: ['***', 'tasks', 'run', '01_unscheduled', 'calculate_stats', 'manual__2023-06-11T03:54:24.205713+00:00', '--job-id', '74', '--raw', '--subdir', 'DAGS_FOLDER/unscheduled.py', '--cfg-path', '/tmp/tmpgk20fquw', '--error-file', '/tmp/tmpuxzf0m2z']
[2023-06-11 04:40:09,190] {standard_task_runner.py:80} INFO - Job 74: Subtask calculate_stats
[2023-06-11 04:40:09,230] {task_command.py:371} INFO - Running <TaskInstance: 01_unscheduled.calculate_stats manual__2023-06-11T03:54:24.205713+00:00 [running]> on host fd847b0d0eb3
[2023-06-11 04:40:09,281] {taskinstance.py:1591} INFO - Exporting the following env vars:
AIRFLOW_CTX_DAG_OWNER=***
AIRFLOW_CTX_DAG_ID=01_unscheduled
AIRFLOW_CTX_TASK_ID=calculate_stats
AIRFLOW_CTX_EXECUTION_DATE=2023-06-11T03:54:24.205713+00:00
AIRFLOW_CTX_TRY_NUMBER=1
AIRFLOW_CTX_DAG_RUN_ID=manual__2023-06-11T03:54:24.205713+00:00
[2023-06-11 04:40:09,283] {taskinstance.py:1909} ERROR - Task failed with exception
Traceback (most recent call last):
  File "/home/airflow/.local/lib/python3.7/site-packages/airflow/operators/python.py", line 171, in execute
    return_value = self.execute_callable()
  File "/home/airflow/.local/lib/python3.7/site-packages/airflow/operators/python.py", line 189, in execute_callable
    return self.python_callable(*self.op_args, **self.op_kwargs)
  File "/opt/airflow/dags/unscheduled.py", line 28, in _calculate_stats
    Path(output_path).parent.mkdir(exist_ok=True)
  File "/usr/local/lib/python3.7/pathlib.py", line 1273, in mkdir
    self._accessor.mkdir(self, mode)
PermissionError: [Errno 13] Permission denied: '/data'
[2023-06-11 04:40:09,294] {taskinstance.py:1420} INFO - Marking task as FAILED. dag_id=01_unscheduled, task_id=calculate_stats, execution_date=20230611T035424, start_date=20230611T044009, end_date=20230611T044009
[2023-06-11 04:40:09,303] {standard_task_runner.py:97} ERROR - Failed to execute job 74 for task calculate_stats ([Errno 13] Permission denied: '/data'; 28878)
[2023-06-11 04:40:09,321] {local_task_job.py:156} INFO - Task exited with return code 1
[2023-06-11 04:40:09,346] {local_task_job.py:273} INFO - 0 downstream tasks scheduled from follow-on schedule check
